Workbook

Sheet Leeme
B1: Dashboard de seguimiento del canal
B2: Fase 12 del proyecto. Documentación completa: 14-fase12-dashboard.md.
B4: Qué celdas rellenas
B5: • Texto azul = datos que escribes tú. Texto negro = fórmulas (no tocar). Texto verde = fórmulas que leen otra hoja.
B6: • Fondo amarillo = parámetros y datos de Studio que conviene revisar cada semana (hoja Resumen e Ideas).
B7: • Columnas con cabecera marrón (Videos, desde 'n_formato'): calculadas.
B9: Rutina
B10: 1. Al publicar: fila del video en 'Videos' (estado, fecha, URL, duración, costo, horas de producción, cumplimiento).
B11: 2. A las 24 h: vistas_24h. A los 7 días: vistas_7d y retencion_30s. A los 28 días: el resto de métricas de Studio.
B12: 3. Cada experimento A/B: fila en 'Experimentos' con la hipótesis ANTES de empezar; el resultado al terminar.
B13: 4. Cada semana: actualiza los datos amarillos de 'Resumen' con la pantalla 'Ganar dinero' de Studio.
B14: 5. Cada mes: revisa 'Ideas' (vuelve a puntuar costo y demanda) y anota aprendizajes en la columna 'aprendizaje'.
... B26: Requisitos del Programa de Socios usados en 'Resumen': fase 10 (support.google.com/youtube/answer/72851 y /12843009, consulta 27-oct-2026).

Sheet Videos
A1: id | B1: estado_video | C1: fecha_publicacion | D1: formato | E1: pilar | F1: tema | G1: keyword_principal | H1: titulo | I1: concepto_miniatura | J1: url | K1: duracion_min | L1: vistas_24h | M1: vistas_7d | N1: vistas_28d | O1: impresiones_28d | P1: ctr_28d | Q1: avd_min | R1: pct_visto | S1: retencion_30s | T1: horas_vistas_28d | U1: subs_ganados_28d | V1: trafico_busqueda | W1: trafico_recomendaciones | X1: trafico_shorts | Y1: trafico_otros | Z1: costo_usd | AA1: horas_produccion | AB1: estado_monetizacion | AC1: cumplimiento_ok | AD1: aprendizaje | AE1: proximo_experimento | AF1: n_formato (aux) | AG1: mediana_prev5_7d | AH1: multiplo_7d | AI1: mediana_prev5_28d | AJ1: multiplo_28d | AK1: mediana_pct_visto_formato | AL1: clasificacion | AM1: costo_por_mil_vistas | AN1: subs_por_mil_vistas
A2: L1 | B2: planificado | C2: 46345 | D2: Largo | E2: P1 | F2: La verdadera historia de La Llorona | G2: la verdadera historia de la llorona | H2: La verdadera historia de La Llorona (según las crónicas) | I2: A: ¿EXISTIÓ? / B: ANTES DE 1519 / C: LO DICE AQUÍ | R2: =IF(AND(ISNUMBER(K2),ISNUMBER(Q2),K2>0),Q2/K2,"") | Y2: =IF(COUNT(V2:X2)=0,"",MAX(0,1-SUM(V2:X2))) | AF2: =IF(D2="","",COUNTIF($D$2:D2,D2)) -> 1 | AG2: {=IF(D2="","",IFERROR(MEDIAN(IF(($D$2:$D$401=D2)*($AF$2:$AF$401>=AF2-5)*($AF$2:$AF$401<=AF2-1)*($M$2:$M$401<>""),$M$2:$M$401)),""))} | AH2: =IF(AND(ISNUMBER(M2),ISNUMBER(AG2)),IF(AG2>0,M2/AG2,""),"") | AI2: {=IF(D2="","",IFERROR(MEDIAN(IF(($D$2:$D$401=D2)*($AF$2:$AF$401>=AF2-5)*($AF$2:$AF$401<=AF2-1)*($N$2:$N$401<>""),$N$2:$N$401)),""))} | AJ2: =IF(AND(ISNUMBER(N2),ISNUMBER(AI2)),IF(AI2>0,N2/AI2,""),"") | AK2: {=IF(D2="","",IFERROR(MEDIAN(IF(($D$2:$D$401=D2)*ISNUMBER($R$2:$R$401),$R$2:$R$401)),""))} | AL2: =IF(ISNUMBER(AJ2),IF(AND(AJ2>=Resumen!$C$5,OR(NOT(ISNUMBER(R2)),NOT(ISNUMBER(AK2)),R2>=AK2)),"Ganador",IF(AJ2<=Resumen!$C$6,"Perdedor","Normal")),IF(ISNUMBER(AH2),IF(AH2>=Resumen!$C$5,"Ganador (7 d, provisional)",IF(AH2<=Resumen!$C$6,"Perdedor (7 d, provisional)","Normal (7 d, provisional)")),"")) | AM2: =IF(AND(ISNUMBER(Z2),ISNUMBER(N2)),IF(N2>0,Z2/N2*1000,""),"") | AN2: =IF(AND(ISNUMBER(U2),ISNUMBER(N2)),IF(N2>0,U2/N2*1000,""),"")
A3: S1 | B3: planificado | C3: 46347 | D3: Short | E3: P1 | F3: Los mexicas oyeron a La Llorona antes de la conquista (según Sahagún) | G3: la llorona | R3: =IF(AND(ISNUMBER(K3),ISNUMBER(Q3),K3>0),Q3/K3,"") | Y3: =IF(COUNT(V3:X3)=0,"",MAX(0,1-SUM(V3:X3))) | AF3: =IF(D3="","",COUNTIF($D$2:D3,D3)) -> 1 | AG3: {=IF(D3="","",IFERROR(MEDIAN(IF(($D$2:$D$401=D3)*($AF$2:$AF$401>=AF3-5)*($AF$2:$AF$401<=AF3-1)*($M$2:$M$401<>""),$M$2:$M$401)),""))} | AH3: =IF(AND(ISNUMBER(M3),ISNUMBER(AG3)),IF(AG3>0,M3/AG3,""),"") | AI3: {=IF(D3="","",IFERROR(MEDIAN(IF(($D$2:$D$401=D3)*($AF$2:$AF$401>=AF3-5)*($AF$2:$AF$401<=AF3-1)*($N$2:$N$401<>""),$N$2:$N$401)),""))} | AJ3: =IF(AND(ISNUMBER(N3),ISNUMBER(AI3)),IF(AI3>0,N3/AI3,""),"") | AK3: {=IF(D3="","",IFERROR(MEDIAN(IF(($D$2:$D$401=D3)*ISNUMBER($R$2:$R$401),$R$2:$R$401)),""))} | AL3: =IF(ISNUMBER(AJ3),IF(AND(AJ3>=Resumen!$C$5,OR(NOT(ISNUMBER(R3)),NOT(ISNUMBER(AK3)),R3>=AK3)),"Ganador",IF(AJ3<=Resumen!$C$6,"Perdedor","Normal")),IF(ISNUMBER(AH3),IF(AH3>=Resumen!$C$5,"Ganador (7 d, provisional)",IF(AH3<=Resumen!$C$6,"Perdedor (7 d, provisional)","Normal (7 d, provisional)")),"")) | AM3: =IF(AND(ISNUMBER(Z3),ISNUMBER(N3)),IF(N3>0,Z3/N3*1000,""),"") | AN3: =IF(AND(ISNUMBER(U3),ISNUMBER(N3)),IF(N3>0,U3/N3*1000,""),"")
A4: S2 | B4: planificado | C4: 46352 | D4: Short | E4: P1 | F4: ¿Cómo se llama La Llorona en tu país? | G4: la llorona | R4: =IF(AND(ISNUMBER(K4),ISNUMBER(Q4),K4>0),Q4/K4,"") | Y4: =IF(COUNT(V4:X4)=0,"",MAX(0,1-SUM(V4:X4))) | AF4: =IF(D4="","",COUNTIF($D$2:D4,D4)) -> 2 | AG4: {=IF(D4="","",IFERROR(MEDIAN(IF(($D$2:$D$401=D4)*($AF$2:$AF$401>=AF4-5)*($AF$2:$AF$401<=AF4-1)*($M$2:$M$401<>""),$M$2:$M$401)),""))} | AH4: =IF(AND(ISNUMBER(M4),ISNUMBER(AG4)),IF(AG4>0,M4/AG4,""),"") | AI4: {=IF(D4="","",IFERROR(MEDIAN(IF(($D$2:$D$401=D4)*($AF$2:$AF$401>=AF4-5)*($AF$2:$AF$401<=AF4-1)*($N$2:$N$401<>""),$N$2:$N$401)),""))} | AJ4: =IF(AND(ISNUMBER(N4),ISNUMBER(AI4)),IF(AI4>0,N4/AI4,""),"") | AK4: {=IF(D4="","",IFERROR(MEDIAN(IF(($D$2:$D$401=D4)*ISNUMBER($R$2:$R$401),$R$2:$R$401)),""))} | AL4: =IF(ISNUMBER(AJ4),IF(AND(AJ4>=Resumen!$C$5,OR(NOT(ISNUMBER(R4)),NOT(ISNUMBER(AK4)),R4>=AK4)),"Ganador",IF(AJ4<=Resumen!$C$6,"Perdedor","Normal")),IF(ISNUMBER(AH4),IF(AH4>=Resumen!$C$5,"Ganador (7 d, provisional)",IF(AH4<=Resumen!$C$6,"Perdedor (7 d, provisional)","Normal (7 d, provisional)")),"")) | AM4: =IF(AND(ISNUMBER(Z4),ISNUMBER(N4)),IF(N4>0,Z4/N4*1000,""),"") | AN4: =IF(AND(ISNUMBER(U4),ISNUMBER(N4)),IF(N4>0,U4/N4*1000,""),"")
A5: L2 | B5: planificado | C5: 46359 | D5: Largo | E5: P2 | F5: ¿Por qué Colombia se llama Colombia? | G5: historia de colombia | H5: ¿Por qué Colombia se llama Colombia? | I5: A: ¿POR QUÉ ÉL? / B: ¿Y ANTES? / C: ERA TODO | R5: =IF(AND(ISNUMBER(K5),ISNUMBER(Q5),K5>0),Q5/K5,"") | Y5: =IF(COUNT(V5:X5)=0,"",MAX(0,1-SUM(V5:X5))) | AF5: =IF(D5="","",COUNTIF($D$2:D5,D5)) -> 2 | AG5: {=IF(D5="","",IFERROR(MEDIAN(IF(($D$2:$D$401=D5)*($AF$2:$AF$401>=AF5-5)*($AF$2:$AF$401<=AF5-1)*($M$2:$M$401<>""),$M$2:$M$401)),""))} | AH5: =IF(AND(ISNUMBER(M5),ISNUMBER(AG5)),IF(AG5>0,M5/AG5,""),"") | AI5: {=IF(D5="","",IFERROR(MEDIAN(IF(($D$2:$D$401=D5)*($AF$2:$AF$401>=AF5-5)*($AF$2:$AF$401<=AF5-1)*($N$2:$N$401<>""),$N$2:$N$401)),""))} | AJ5: =IF(AND(ISNUMBER(N5),ISNUMBER(AI5)),IF(AI5>0,N5/AI5,""),"") | AK5: {=IF(D5="","",IFERROR(MEDIAN(IF(($D$2:$D$401=D5)*ISNUMBER($R$2:$R$401),$R$2:$R$401)),""))} | AL5: =IF(ISNUMBER(AJ5),IF(AND(AJ5>=Resumen!$C$5,OR(NOT(ISNUMBER(R5)),NOT(ISNUMBER(AK5)),R5>=AK5)),"Ganador",IF(AJ5<=Resumen!$C$6,"Perdedor","Normal")),IF(ISNUMBER(AH5),IF(AH5>=Resumen!$C$5,"Ganador (7 d, provisional)",IF(AH5<=Resumen!$C$6,"Perdedor (7 d, provisional)","Normal (7 d, provisional)")),"")) | AM5: =IF(AND(ISNUMBER(Z5),ISNUMBER(N5)),IF(N5>0,Z5/N5*1000,""),"") | AN5: =IF(AND(ISNUMBER(U5),ISNUMBER(N5)),IF(N5>0,U5/N5*1000,""),"")
A6: S3 | B6: planificado | C6: 46361 | D6: Short | E6: P2 | F6: Colombia se llamó Estados Unidos de Colombia | G6: historia de colombia | R6: =IF(AND(ISNUMBER(K6),ISNUMBER(Q6),K6>0),Q6/K6,"") | Y6: =IF(COUNT(V6:X6)=0,"",MAX(0,1-SUM(V6:X6))) | AF6: =IF(D6="","",COUNTIF($D$2:D6,D6)) -> 3 | AG6: {=IF(D6="","",IFERROR(MEDIAN(IF(($D$2:$D$401=D6)*($AF$2:$AF$401>=AF6-5)*($AF$2:$AF$401<=AF6-1)*($M$2:$M$401<>""),$M$2:$M$401)),""))} | AH6: =IF(AND(ISNUMBER(M6),ISNUMBER(AG6)),IF(AG6>0,M6/AG6,""),"") | AI6: {=IF(D6="","",IFERROR(MEDIAN(IF(($D$2:$D$401=D6)*($AF$2:$AF$401>=AF6-5)*($AF$2:$AF$401<=AF6-1)*($N$2:$N$401<>""),$N$2:$N$401)),""))} | AJ6: =IF(AND(ISNUMBER(N6),ISNUMBER(AI6)),IF(AI6>0,N6/AI6,""),"") | AK6: {=IF(D6="","",IFERROR(MEDIAN(IF(($D$2:$D$401=D6)*ISNUMBER($R$2:$R$401),$R$2:$R$401)),""))} | AL6: =IF(ISNUMBER(AJ6),IF(AND(AJ6>=Resumen!$C$5,OR(NOT(ISNUMBER(R6)),NOT(ISNUMBER(AK6)),R6>=AK6)),"Ganador",IF(AJ6<=Resumen!$C$6,"Perdedor","Normal")),IF(ISNUMBER(AH6),IF(AH6>=Resumen!$C$5,"Ganador (7 d, provisional)",IF(AH6<=Resumen!$C$6,"Perdedor (7 d, provisional)","Normal (7 d, provisional)")),"")) | AM6: =IF(AND(ISNUMBER(Z6),ISNUMBER(N6)),IF(N6>0,Z6/N6*1000,""),"") | AN6: =IF(AND(ISNUMBER(U6),ISNUMBER(N6)),IF(N6>0,U6/N6*1000,""),"")
A7: S4 | B7: planificado | C7: 46366 | D7: Short | E7: P2 | F7: El nombre 'Colombia' era para todo el continente | G7: historia de colombia | R7: =IF(AND(ISNUMBER(K7),ISNUMBER(Q7),K7>0),Q7/K7,"") | Y7: =IF(COUNT(V7:X7)=0,"",MAX(0,1-SUM(V7:X7))) | AF7: =IF(D7="","",COUNTIF($D$2:D7,D7)) -> 4 | AG7: {=IF(D7="","",IFERROR(MEDIAN(IF(($D$2:$D$401=D7)*($AF$2:$AF$401>=AF7-5)*($AF$2:$AF$401<=AF7-1)*($M$2:$M$401<>""),$M$2:$M$401)),""))} | AH7: =IF(AND(ISNUMBER(M7),ISNUMBER(AG7)),IF(AG7>0,M7/AG7,""),"") | AI7: {=IF(D7="","",IFERROR(MEDIAN(IF(($D$2:$D$401=D7)*($AF$2:$AF$401>=AF7-5)*($AF$2:$AF$401<=AF7-1)*($N$2:$N$401<>""),$N$2:$N$401)),""))} | AJ7: =IF(AND(ISNUMBER(N7),ISNUMBER(AI7)),IF(AI7>0,N7/AI7,""),"") | AK7: {=IF(D7="","",IFERROR(MEDIAN(IF(($D$2:$D$401=D7)*ISNUMBER($R$2:$R$401),$R$2:$R$401)),""))} | AL7: =IF(ISNUMBER(AJ7),IF(AND(AJ7>=Resumen!$C$5,OR(NOT(ISNUMBER(R7)),NOT(ISNUMBER(AK7)),R7>=AK7)),"Ganador",IF(AJ7<=Resumen!$C$6,"Perdedor","Normal")),IF(ISNUMBER(AH7),IF(AH7>=Resumen!$C$5,"Ganador (7 d, provisional)",IF(AH7<=Resumen!$C$6,"Perdedor (7 d, provisional)","Normal (7 d, provisional)")),"")) | AM7: =IF(AND(ISNUMBER(Z7),ISNUMBER(N7)),IF(N7>0,Z7/N7*1000,""),"") | AN7: =IF(AND(ISNUMBER(U7),ISNUMBER(N7)),IF(N7>0,U7/N7*1000,""),"")
A8: L3 | B8: planificado | C8: 46373 | D8: Largo | E8: P1 | F8: El Dorado: lo que sí existió | G8: el dorado leyenda | H8: El Dorado sí existió (pero no era una ciudad) | I8: A: NO ERA CIUDAD / B: ESTO SÍ / C: ¿DÓNDE ESTÁ? | R8: =IF(AND(ISNUMBER(K8),ISNUMBER(Q8),K8>0),Q8/K8,"") | Y8: =IF(COUNT(V8:X8)=0,"",MAX(0,1-SUM(V8:X8))) | AF8: =IF(D8="","",COUNTIF($D$2:D8,D8)) -> 3 | AG8: {=IF(D8="","",IFERROR(MEDIAN(IF(($D$2:$D$401=D8)*($AF$2:$AF$401>=AF8-5)*($AF$2:$AF$401<=AF8-1)*($M$2:$M$401<>""),$M$2:$M$401)),""))} | AH8: =IF(AND(ISNUMBER(M8),ISNUMBER(AG8)),IF(AG8>0,M8/AG8,""),"") | AI8: {=IF(D8="","",IFERROR(MEDIAN(IF(($D$2:$D$401=D8)*($AF$2:$AF$401>=AF8-5)*($AF$2:$AF$401<=AF8-1)*($N$2:$N$401<>""),$N$2:$N$401)),""))} | AJ8: =IF(AND(ISNUMBER(N8),ISNUMBER(AI8)),IF(AI8>0,N8/AI8,""),"") | AK8: {=IF(D8="","",IFERROR(MEDIAN(IF(($D$2:$D$401=D8)*ISNUMBER($R$2:$R$401),$R$2:$R$401)),""))} | AL8: =IF(ISNUMBER(AJ8),IF(AND(AJ8>=Resumen!$C$5,OR(NOT(ISNUMBER(R8)),NOT(ISNUMBER(AK8)),R8>=AK8)),"Ganador",IF(AJ8<=Resumen!$C$6,"Perdedor","Normal")),IF(ISNUMBER(AH8),IF(AH8>=Resumen!$C$5,"Ganador (7 d, provisional)",IF(AH8<=Resumen!$C$6,"Perdedor (7 d, provisional)","Normal (7 d, provisional)")),"")) | AM8: =IF(AND(ISNUMBER(Z8),ISNUMBER(N8)),IF(N8>0,Z8/N8*1000,""),"") | AN8: =IF(AND(ISNUMBER(U8),ISNUMBER(N8)),IF(N8>0,U8/N8*1000,""),"")
A9: S5 | B9: planificado | C9: 46375 | D9: Short | E9: P1 | F9: El Dorado no era una ciudad. Era un hombre | G9: el dorado | R9: =IF(AND(ISNUMBER(K9),ISNUMBER(Q9),K9>0),Q9/K9,"") | Y9: =IF(COUNT(V9:X9)=0,"",MAX(0,1-SUM(V9:X9))) | AF9: =IF(D9="","",COUNTIF($D$2:D9,D9)) -> 5 | AG9: {=IF(D9="","",IFERROR(MEDIAN(IF(($D$2:$D$401=D9)*($AF$2:$AF$401>=AF9-5)*($AF$2:$AF$401<=AF9-1)*($M$2:$M$401<>""),$M$2:$M$401)),""))} | AH9: =IF(AND(ISNUMBER(M9),ISNUMBER(AG9)),IF(AG9>0,M9/AG9,""),"") | AI9: {=IF(D9="","",IFERROR(MEDIAN(IF(($D$2:$D$401=D9)*($AF$2:$AF$401>=AF9-5)*($AF$2:$AF$401<=AF9-1)*($N$2:$N$401<>""),$N$2:$N$401)),""))} | AJ9: =IF(AND(ISNUMBER(N9),ISNUMBER(AI9)),IF(AI9>0,N9/AI9,""),"") | AK9: {=IF(D9="","",IFERROR(MEDIAN(IF(($D$2:$D$401=D9)*ISNUMBER($R$2:$R$401),$R$2:$R$401)),""))} | AL9: =IF(ISNUMBER(AJ9),IF(AND(AJ9>=Resumen!$C$5,OR(NOT(ISNUMBER(R9)),NOT(ISNUMBER(AK9)),R9>=AK9)),"Ganador",IF(AJ9<=Resumen!$C$6,"Perdedor","Normal")),IF(ISNUMBER(AH9),IF(AH9>=Resumen!$C$5,"Ganador (7 d, provisional)",IF(AH9<=Resumen!$C$6,"Perdedor (7 d, provisional)","Normal (7 d, provisional)")),"")) | AM9: =IF(AND(ISNUMBER(Z9),ISNUMBER(N9)),IF(N9>0,Z9/N9*1000,""),"") | AN9: =IF(AND(ISNUMBER(U9),ISNUMBER(N9)),IF(N9>0,U9/N9*1000,""),"")
A10: S6 | B10: planificado | C10: 46380 | D10: Short | E10: P1 | F10: Intentaron vaciar una laguna para sacar el oro | G10: laguna de guatavita | R10: =IF(AND(ISNUMBER(K10),ISNUMBER(Q10),K10>0),Q10/K10,"") | Y10: =IF(COUNT(V10:X10)=0,"",MAX(0,1-SUM(V10:X10))) | AF10: =IF(D10="","",COUNTIF($D$2:D10,D10)) -> 6 | AG10: {=IF(D10="","",IFERROR(MEDIAN(IF(($D$2:$D$401=D10)*($AF$2:$AF$401>=AF10-5)*($AF$2:$AF$401<=AF10-1)*($M$2:$M$401<>""),$M$2:$M$401)),""))} | AH10: =IF(AND(ISNUMBER(M10),ISNUMBER(AG10)),IF(AG10>0,M10/AG10,""),"") | AI10: {=IF(D10="","",IFERROR(MEDIAN(IF(($D$2:$D$401=D10)*($AF$2:$AF$401>=AF10-5)*($AF$2:$AF$401<=AF10-1)*($N$2:$N$401<>""),$N$2:$N$401)),""))} | AJ10: =IF(AND(ISNUMBER(N10),ISNUMBER(AI10)),IF(AI10>0,N10/AI10,""),"") | AK10: {=IF(D10="","",IFERROR(MEDIAN(IF(($D$2:$D$401=D10)*ISNUMBER($R$2:$R$401),$R$2:$R$401)),""))} | AL10: =IF(ISNUMBER(AJ10),IF(AND(AJ10>=Resumen!$C$5,OR(NOT(ISNUMBER(R10)),NOT(ISNUMBER(AK10)),R10>=AK10)),"Ganador",IF(AJ10<=Resumen!$C$6,"Perdedor","Normal")),IF(ISNUMBER(AH10),IF(AH10>=Resumen!$C$5,"Ganador (7 d, provisional)",IF(AH10<=Resumen!$C$6,"Perdedor (7 d, provisional)","Normal (7 d, provisional)")),"")) | AM10: =IF(AND(ISNUMBER(Z10),ISNUMBER(N10)),IF(N10>0,Z10/N10*1000,""),"") | AN10: =IF(AND(ISNUMBER(U10),ISNUMBER(N10)),IF(N10>0,U10/N10*1000,""),"")
A11: L4 | B11: planificado | C11: 46386 | D11: Largo | E11: P1 | F11: El chupacabras: cómo nació un monstruo moderno | G11: la leyenda del chupacabras | H11: El chupacabras: cómo nació un monstruo en 1995 | I11: A: NACIÓ EN 1995 / B: ¿REAL? / C: LO CREÓ LA TV | R11: =IF(AND(ISNUMBER(K11),ISNUMBER(Q11),K11>0),Q11/K11,"") | Y11: =IF(COUNT(V11:X11)=0,"",MAX(0,1-SUM(V11:X11))) | AF11: =IF(D11="","",COUNTIF($D$2:D11,D11)) -> 4 | AG11: {=IF(D11="","",IFERROR(MEDIAN(IF(($D$2:$D$401=D11)*($AF$2:$AF$401>=AF11-5)*($AF$2:$AF$401<=AF11-1)*($M$2:$M$401<>""),$M$2:$M$401)),""))} | AH11: =IF(AND(ISNUMBER(M11),ISNUMBER(AG11)),IF(AG11>0,M11/AG11,""),"") | AI11: {=IF(D11="","",IFERROR(MEDIAN(IF(($D$2:$D$401=D11)*($AF$2:$AF$401>=AF11-5)*($AF$2:$AF$401<=AF11-1)*($N$2:$N$401<>""),$N$2:$N$401)),""))} | AJ11: =IF(AND(ISNUMBER(N11),ISNUMBER(AI11)),IF(AI11>0,N11/AI11,""),"") | AK11: {=IF(D11="","",IFERROR(MEDIAN(IF(($D$2:$D$401=D11)*ISNUMBER($R$2:$R$401),$R$2:$R$401)),""))} | AL11: =IF(ISNUMBER(AJ11),IF(AND(AJ11>=Resumen!$C$5,OR(NOT(ISNUMBER(R11)),NOT(ISNUMBER(AK11)),R11>=AK11)),"Ganador",IF(AJ11<=Resumen!$C$6,"Perdedor","Normal")),IF(ISNUMBER(AH11),IF(AH11>=Resumen!$C$5,"Ganador (7 d, provisional)",IF(AH11<=Resumen!$C$6,"Perdedor (7 d, provisional)","Normal (7 d, provisional)")),"")) | AM11: =IF(AND(ISNUMBER(Z11),ISNUMBER(N11)),IF(N11>0,Z11/N11*1000,""),"") | AN11: =IF(AND(ISNUMBER(U11),ISNUMBER(N11)),IF(N11>0,U11/N11*1000,""),"")
A12: S7 | B12: planificado | C12: 46389 | D12: Short | E12: P1 | F12: El chupacabras tiene fecha de nacimiento | G12: chupacabras | R12: =IF(AND(ISNUMBER(K12),ISNUMBER(Q12),K12>0),Q12/K12,"") | Y12: =IF(COUNT(V12:X12)=0,"",MAX(0,1-SUM(V12:X12))) | AF12: =IF(D12="","",COUNTIF($D$2:D12,D12)) -> 7 | AG12: {=IF(D12="","",IFERROR(MEDIAN(IF(($D$2:$D$401=D12)*($AF$2:$AF$401>=AF12-5)*($AF$2:$AF$401<=AF12-1)*($M$2:$M$401<>""),$M$2:$M$401)),""))} | AH12: =IF(AND(ISNUMBER(M12),ISNUMBER(AG12)),IF(AG12>0,M12/AG12,""),"") | AI12: {=IF(D12="","",IFERROR(MEDIAN(IF(($D$2:$D$401=D12)*($AF$2:$AF$401>=AF12-5)*($AF$2:$AF$401<=AF12-1)*($N$2:$N$401<>""),$N$2:$N$401)),""))} | AJ12: =IF(AND(ISNUMBER(N12),ISNUMBER(AI12)),IF(AI12>0,N12/AI12,""),"") | AK12: {=IF(D12="","",IFERROR(MEDIAN(IF(($D$2:$D$401=D12)*ISNUMBER($R$2:$R$401),$R$2:$R$401)),""))} | AL12: =IF(ISNUMBER(AJ12),IF(AND(AJ12>=Resumen!$C$5,OR(NOT(ISNUMBER(R12)),NOT(ISNUMBER(AK12)),R12>=AK12)),"Ganador",IF(AJ12<=Resumen!$C$6,"Perdedor","Normal")),IF(ISNUMBER(AH12),IF(AH12>=Resumen!$C$5,"Ganador (7 d, provisional)",IF(AH12<=Resumen!$C$6,"Perdedor (7 d, provisional)","Normal (7 d, provisional)")),"")) | AM12: =IF(AND(ISNUMBER(Z12),ISNUMBER(N12)),IF(N12>0,Z12/N12*1000,""),"") | AN12: =IF(AND(ISNUMBER(U12),ISNUMBER(N12)),IF(N12>0,U12/N12*1000,""),"")
A13: S8 | B13: planificado | C13: 46393 | D13: Short | E13: P1 | F13: Quién le puso el nombre al chupacabras (verificar) | G13: chupacabras | R13: =IF(AND(ISNUMBER(K13),ISNUMBER(Q13),K13>0),Q13/K13,"") | Y13: =IF(COUNT(V13:X13)=0,"",MAX(0,1-SUM(V13:X13))) | AF13: =IF(D13="","",COUNTIF($D$2:D13,D13)) -> 8 | AG13: {=IF(D13="","",IFERROR(MEDIAN(IF(($D$2:$D$401=D13)*($AF$2:$AF$401>=AF13-5)*($AF$2:$AF$401<=AF13-1)*($M$2:$M$401<>""),$M$2:$M$401)),""))} | AH13: =IF(AND(ISNUMBER(M13),ISNUMBER(AG13)),IF(AG13>0,M13/AG13,""),"") | AI13: {=IF(D13="","",IFERROR(MEDIAN(IF(($D$2:$D$401=D13)*($AF$2:$AF$401>=AF13-5)*($AF$2:$AF$401<=AF13-1)*($N$2:$N$401<>""),$N$2:$N$401)),""))} | AJ13: =IF(AND(ISNUMBER(N13),ISNUMBER(AI13)),IF(AI13>0,N13/AI13,""),"") | AK13: {=IF(D13="","",IFERROR(MEDIAN(IF(($D$2:$D$401=D13)*ISNUMBER($R$2:$R$401),$R$2:$R$401)),""))} | AL13: =IF(ISNUMBER(AJ13),IF(AND(AJ13>=Resumen!$C$5,OR(NOT(ISNUMBER(R13)),NOT(ISNUMBER(AK13)),R13>=AK13)),"Ganador",IF(AJ13<=Resumen!$C$6,"Perdedor","Normal")),IF(ISNUMBER(AH13),IF(AH13>=Resumen!$C$5,"Ganador (7 d, provisional)",IF(AH13<=Resumen!$C$6,"Perdedor (7 d, provisional)","Normal (7 d, provisional)")),"")) | AM13: =IF(AND(ISNUMBER(Z13),ISNUMBER(N13)),IF(N13>0,Z13/N13*1000,""),"") | AN13: =IF(AND(ISNUMBER(U13),ISNUMBER(N13)),IF(N13>0,U13/N13*1000,""),"")
A14: S9 | B14: planificado | C14: 46396 | D14: Short | E14: P2 | F14: Colombia lleva el nombre de alguien que nunca vino (solo si se verifica) | G14: historia de colombia | R14: =IF(AND(ISNUMBER(K14),ISNUMBER(Q14),K14>0),Q14/K14,"") | Y14: =IF(COUNT(V14:X14)=0,"",MAX(0,1-SUM(V14:X14))) | AF14: =IF(D14="","",COUNTIF($D$2:D14,D14)) -> 9 | AG14: {=IF(D14="","",IFERROR(MEDIAN(IF(($D$2:$D$401=D14)*($AF$2:$AF$401>=AF14-5)*($AF$2:$AF$401<=AF14-1)*($M$2:$M$401<>""),$M$2:$M$401)),""))} | AH14: =IF(AND(ISNUMBER(M14),ISNUMBER(AG14)),IF(AG14>0,M14/AG14,""),"") | AI14: {=IF(D14="","",IFERROR(MEDIAN(IF(($D$2:$D$401=D14)*($AF$2:$AF$401>=AF14-5)*($AF$2:$AF$401<=AF14-1)*($N$2:$N$401<>""),$N$2:$N$401)),""))} | AJ14: =IF(AND(ISNUMBER(N14),ISNUMBER(AI14)),IF(AI14>0,N14/AI14,""),"") | AK14: {=IF(D14="","",IFERROR(MEDIAN(IF(($D$2:$D$401=D14)*ISNUMBER($R$2:$R$401),$R$2:$R$401)),""))} | AL14: =IF(ISNUMBER(AJ14),IF(AND(AJ14>=Resumen!$C$5,OR(NOT(ISNUMBER(R14)),NOT(ISNUMBER(AK14)),R14>=AK14)),"Ganador",IF(AJ14<=Resumen!$C$6,"Perdedor","Normal")),IF(ISNUMBER(AH14),IF(AH14>=Resumen!$C$5,"Ganador (7 d, provisional)",IF(AH14<=Resumen!$C$6,"Perdedor (7 d, provisional)","Normal (7 d, provisional)")),"")) | AM14: =IF(AND(ISNUMBER(Z14),ISNUMBER(N14)),IF(N14>0,Z14/N14*1000,""),"") | AN14: =IF(AND(ISNUMBER(U14),ISNUMBER(N14)),IF(N14>0,U14/N14*1000,""),"")
A15: L5 | B15: planificado | C15: 46401 | D15: Largo | E15: P2 | F15: ¿De verdad unos cientos de españoles conquistaron a los mexicas? | G15: conquista de mexico | H15: ¿De verdad 500 españoles conquistaron a los mexicas? | I15: A: ¿SOLO 500? / B: NO ESTABA SOLO / C: TODOS CONTRA… | R15: =IF(AND(ISNUMBER(K15),ISNUMBER(Q15),K15>0),Q15/K15,"") | Y15: =IF(COUNT(V15:X15)=0,"",MAX(0,1-SUM(V15:X15))) | AF15: =IF(D15="","",COUNTIF($D$2:D15,D15)) -> 5 | AG15: {=IF(D15="","",IFERROR(MEDIAN(IF(($D$2:$D$401=D15)*($AF$2:$AF$401>=AF15-5)*($AF$2:$AF$401<=AF15-1)*($M$2:$M$401<>""),$M$2:$M$401)),""))} | AH15: =IF(AND(ISNUMBER(M15),ISNUMBER(AG15)),IF(AG15>0,M15/AG15,""),"") | AI15: {=IF(D15="","",IFERROR(MEDIAN(IF(($D$2:$D$401=D15)*($AF$2:$AF$401>=AF15-5)*($AF$2:$AF$401<=AF15-1)*($N$2:$N$401<>""),$N$2:$N$401)),""))} | AJ15: =IF(AND(ISNUMBER(N15),ISNUMBER(AI15)),IF(AI15>0,N15/AI15,""),"") | AK15: {=IF(D15="","",IFERROR(MEDIAN(IF(($D$2:$D$401=D15)*ISNUMBER($R$2:$R$401),$R$2:$R$401)),""))} | AL15: =IF(ISNUMBER(AJ15),IF(AND(AJ15>=Resumen!$C$5,OR(NOT(ISNUMBER(R15)),NOT(ISNUMBER(AK15)),R15>=AK15)),"Ganador",IF(AJ15<=Resumen!$C$6,"Perdedor","Normal")),IF(ISNUMBER(AH15),IF(AH15>=Resumen!$C$5,"Ganador (7 d, provisional)",IF(AH15<=Resumen!$C$6,"Perdedor (7 d, provisional)","Normal (7 d, provisional)")),"")) | AM15: =IF(AND(ISNUMBER(Z15),ISNUMBER(N15)),IF(N15>0,Z15/N15*1000,""),"") | AN15: =IF(AND(ISNUMBER(U15),ISNUMBER(N15)),IF(N15>0,U15/N15*1000,""),"")
A16: S10 | B16: planificado | C16: 46403 | D16: Short | E16: P2 | F16: Cortés no conquistó México solo | G16: hernan cortes | R16: =IF(AND(ISNUMBER(K16),ISNUMBER(Q16),K16>0),Q16/K16,"") | Y16: =IF(COUNT(V16:X16)=0,"",MAX(0,1-SUM(V16:X16))) | AF16: =IF(D16="","",COUNTIF($D$2:D16,D16)) -> 10 | AG16: {=IF(D16="","",IFERROR(MEDIAN(IF(($D$2:$D$401=D16)*($AF$2:$AF$401>=AF16-5)*($AF$2:$AF$401<=AF16-1)*($M$2:$M$401<>""),$M$2:$M$401)),""))} | AH16: =IF(AND(ISNUMBER(M16),ISNUMBER(AG16)),IF(AG16>0,M16/AG16,""),"") | AI16: {=IF(D16="","",IFERROR(MEDIAN(IF(($D$2:$D$401=D16)*($AF$2:$AF$401>=AF16-5)*($AF$2:$AF$401<=AF16-1)*($N$2:$N$401<>""),$N$2:$N$401)),""))} | AJ16: =IF(AND(ISNUMBER(N16),ISNUMBER(AI16)),IF(AI16>0,N16/AI16,""),"") | AK16: {=IF(D16="","",IFERROR(MEDIAN(IF(($D$2:$D$401=D16)*ISNUMBER($R$2:$R$401),$R$2:$R$401)),""))} | AL16: =IF(ISNUMBER(AJ16),IF(AND(AJ16>=Resumen!$C$5,OR(NOT(ISNUMBER(R16)),NOT(ISNUMBER(AK16)),R16>=AK16)),"Ganador",IF(AJ16<=Resumen!$C$6,"Perdedor","Normal")),IF(ISNUMBER(AH16),IF(AH16>=Resumen!$C$5,"Ganador (7 d, provisional)",IF(AH16<=Resumen!$C$6,"Perdedor (7 d, provisional)","Normal (7 d, provisional)")),"")) | AM16: =IF(AND(ISNUMBER(Z16),ISNUMBER(N16)),IF(N16>0,Z16/N16*1000,""),"") | AN16: =IF(AND(ISNUMBER(U16),ISNUMBER(N16)),IF(N16>0,U16/N16*1000,""),"")
A17: S11 | B17: planificado | C17: 46407 | D17: Short | E17: P2 | F17: El arma más letal de la conquista no era una espada | G17: conquista de mexico | R17: =IF(AND(ISNUMBER(K17),ISNUMBER(Q17),K17>0),Q17/K17,"") | Y17: =IF(COUNT(V17:X17)=0,"",MAX(0,1-SUM(V17:X17))) | AF17: =IF(D17="","",COUNTIF($D$2:D17,D17)) -> 11 | AG17: {=IF(D17="","",IFERROR(MEDIAN(IF(($D$2:$D$401=D17)*($AF$2:$AF$401>=AF17-5)*($AF$2:$AF$401<=AF17-1)*($M$2:$M$401<>""),$M$2:$M$401)),""))} | AH17: =IF(AND(ISNUMBER(M17),ISNUMBER(AG17)),IF(AG17>0,M17/AG17,""),"") | AI17: {=IF(D17="","",IFERROR(MEDIAN(IF(($D$2:$D$401=D17)*($AF$2:$AF$401>=AF17-5)*($AF$2:$AF$401<=AF17-1)*($N$2:$N$401<>""),$N$2:$N$401)),""))} | AJ17: =IF(AND(ISNUMBER(N17),ISNUMBER(AI17)),IF(AI17>0,N17/AI17,""),"") | AK17: {=IF(D17="","",IFERROR(MEDIAN(IF(($D$2:$D$401=D17)*ISNUMBER($R$2:$R$401),$R$2:$R$401)),""))} | AL17: =IF(ISNUMBER(AJ17),IF(AND(AJ17>=Resumen!$C$5,OR(NOT(ISNUMBER(R17)),NOT(ISNUMBER(AK17)),R17>=AK17)),"Ganador",IF(AJ17<=Resumen!$C$6,"Perdedor","Normal")),IF(ISNUMBER(AH17),IF(AH17>=Resumen!$C$5,"Ganador (7 d, provisional)",IF(AH17<=Resumen!$C$6,"Perdedor (7 d, provisional)","Normal (7 d, provisional)")),"")) | AM17: =IF(AND(ISNUMBER(Z17),ISNUMBER(N17)),IF(N17>0,Z17/N17*1000,""),"") | AN17: =IF(AND(ISNUMBER(U17),ISNUMBER(N17)),IF(N17>0,U17/N17*1000,""),"")
A18: S12 | B18: planificado | C18: 46410 | D18: Short | E18: P2 | F18: Ciudad de México está construida sobre un lago | G18: historia de mexico | R18: =IF(AND(ISNUMBER(K18),ISNUMBER(Q18),K18>0),Q18/K18,"") | Y18: =IF(COUNT(V18:X18)=0,"",MAX(0,1-SUM(V18:X18))) | AF18: =IF(D18="","",COUNTIF($D$2:D18,D18)) -> 12 | AG18: {=IF(D18="","",IFERROR(MEDIAN(IF(($D$2:$D$401=D18)*($AF$2:$AF$401>=AF18-5)*($AF$2:$AF$401<=AF18-1)*($M$2:$M$401<>""),$M$2:$M$401)),""))} | AH18: =IF(AND(ISNUMBER(M18),ISNUMBER(AG18)),IF(AG18>0,M18/AG18,""),"") | AI18: {=IF(D18="","",IFERROR(MEDIAN(IF(($D$2:$D$401=D18)*($AF$2:$AF$401>=AF18-5)*($AF$2:$AF$401<=AF18-1)*($N$2:$N$401<>""),$N$2:$N$401)),""))} | AJ18: =IF(AND(ISNUMBER(N18),ISNUMBER(AI18)),IF(AI18>0,N18/AI18,""),"") | AK18: {=IF(D18="","",IFERROR(MEDIAN(IF(($D$2:$D$401=D18)*ISNUMBER($R$2:$R$401),$R$2:$R$401)),""))} | AL18: =IF(ISNUMBER(AJ18),IF(AND(AJ18>=Resumen!$C$5,OR(NOT(ISNUMBER(R18)),NOT(ISNUMBER(AK18)),R18>=AK18)),"Ganador",IF(AJ18<=Resumen!$C$6,"Perdedor","Normal")),IF(ISNUMBER(AH18),IF(AH18>=Resumen!$C$5,"Ganador (7 d, provisional)",IF(AH18<=Resumen!$C$6,"Perdedor (7 d, provisional)","Normal (7 d, provisional)")),"")) | AM18: =IF(AND(ISNUMBER(Z18),ISNUMBER(N18)),IF(N18>0,Z18/N18*1000,""),"") | AN18: =IF(AND(ISNUMBER(U18),ISNUMBER(N18)),IF(N18>0,U18/N18*1000,""),"")
A19: L6 | B19: planificado | C19: 46415 | D19: Largo | E19: P2 | F19: ¿Por qué la Ciudad de México está sobre un lago? | G19: historia de mexico | H19: ¿Por qué la Ciudad de México está sobre un lago? | I19: A: AQUÍ HABÍA AGUA / B: SE HUNDE / C: ¿POR QUÉ AQUÍ? | R19: =IF(AND(ISNUMBER(K19),ISNUMBER(Q19),K19>0),Q19/K19,"") | Y19: =IF(COUNT(V19:X19)=0,"",MAX(0,1-SUM(V19:X19))) | AF19: =IF(D19="","",COUNTIF($D$2:D19,D19)) -> 6 | AG19: {=IF(D19="","",IFERROR(MEDIAN(IF(($D$2:$D$401=D19)*($AF$2:$AF$401>=AF19-5)*($AF$2:$AF$401<=AF19-1)*($M$2:$M$401<>""),$M$2:$M$401)),""))} | AH19: =IF(AND(ISNUMBER(M19),ISNUMBER(AG19)),IF(AG19>0,M19/AG19,""),"") | AI19: {=IF(D19="","",IFERROR(MEDIAN(IF(($D$2:$D$401=D19)*($AF$2:$AF$401>=AF19-5)*($AF$2:$AF$401<=AF19-1)*($N$2:$N$401<>""),$N$2:$N$401)),""))} | AJ19: =IF(AND(ISNUMBER(N19),ISNUMBER(AI19)),IF(AI19>0,N19/AI19,""),"") | AK19: {=IF(D19="","",IFERROR(MEDIAN(IF(($D$2:$D$401=D19)*ISNUMBER($R$2:$R$401),$R$2:$R$401)),""))} | AL19: =IF(ISNUMBER(AJ19),IF(AND(AJ19>=Resumen!$C$5,OR(NOT(ISNUMBER(R19)),NOT(ISNUMBER(AK19)),R19>=AK19)),"Ganador",IF(AJ19<=Resumen!$C$6,"Perdedor","Normal")),IF(ISNUMBER(AH19),IF(AH19>=Resumen!$C$5,"Ganador (7 d, provisional)",IF(AH19<=Resumen!$C$6,"Perdedor (7 d, provisional)","Normal (7 d, provisional)")),"")) | AM19: =IF(AND(ISNUMBER(Z19),ISNUMBER(N19)),IF(N19>0,Z19/N19*1000,""),"") | AN19: =IF(AND(ISNUMBER(U19),ISNUMBER(N19)),IF(N19>0,U19/N19*1000,""),"")
A20: S13 | B20: planificado | C20: 46417 | D20: Short | E20: P2 | F20: La ciudad se hunde cada año (con fuente oficial) | G20: cdmx | R20: =IF(AND(ISNUMBER(K20),ISNUMBER(Q20),K20>0),Q20/K20,"") | Y20: =IF(COUNT(V20:X20)=0,"",MAX(0,1-SUM(V20:X20))) | AF20: =IF(D20="","",COUNTIF($D$2:D20,D20)) -> 13 | AG20: {=IF(D20="","",IFERROR(MEDIAN(IF(($D$2:$D$401=D20)*($AF$2:$AF$401>=AF20-5)*($AF$2:$AF$401<=AF20-1)*($M$2:$M$401<>""),$M$2:$M$401)),""))} | AH20: =IF(AND(ISNUMBER(M20),ISNUMBER(AG20)),IF(AG20>0,M20/AG20,""),"") | AI20: {=IF(D20="","",IFERROR(MEDIAN(IF(($D$2:$D$401=D20)*($AF$2:$AF$401>=AF20-5)*($AF$2:$AF$401<=AF20-1)*($N$2:$N$401<>""),$N$2:$N$401)),""))} | AJ20: =IF(AND(ISNUMBER(N20),ISNUMBER(AI20)),IF(AI20>0,N20/AI20,""),"") | AK20: {=IF(D20="","",IFERROR(MEDIAN(IF(($D$2:$D$401=D20)*ISNUMBER($R$2:$R$401),$R$2:$R$401)),""))} | AL20: =IF(ISNUMBER(AJ20),IF(AND(AJ20>=Resumen!$C$5,OR(NOT(ISNUMBER(R20)),NOT(ISNUMBER(AK20)),R20>=AK20)),"Ganador",IF(AJ20<=Resumen!$C$6,"Perdedor","Normal")),IF(ISNUMBER(AH20),IF(AH20>=Resumen!$C$5,"Ganador (7 d, provisional)",IF(AH20<=Resumen!$C$6,"Perdedor (7 d, provisional)","Normal (7 d, provisional)")),"")) | AM20: =IF(AND(ISNUMBER(Z20),ISNUMBER(N20)),IF(N20>0,Z20/N20*1000,""),"") | AN20: =IF(AND(ISNUMBER(U20),ISNUMBER(N20)),IF(N20>0,U20/N20*1000,""),"")
R21: =IF(AND(ISNUMBER(K21),ISNUMBER(Q21),K21>0),Q21/K21,"") | Y21: =IF(COUNT(V21:X21)=0,"",MAX(0,1-SUM(V21:X21))) | AF21: =IF(D21="","",COUNTIF($D$2:D21,D21)) | AG21: {=IF(D21="","",IFERROR(MEDIAN(IF(($D$2:$D$401=D21)*($AF$2:$AF$401>=AF21-5)*($AF$2:$AF$401<=AF21-1)*($M$2:$M$401<>""),$M$2:$M$401)),""))} | AH21: =IF(AND(ISNUMBER(M21),ISNUMBER(AG21)),IF(AG21>0,M21/AG21,""),"") | AI21: {=IF(D21="","",IFERROR(MEDIAN(IF(($D$2:$D$401=D21)*($AF$2:$AF$401>=AF21-5)*($AF$2:$AF$401<=AF21-1)*($N$2:$N$401<>""),$N$2:$N$401)),""))} | AJ21: =IF(AND(ISNUMBER(N21),ISNUMBER(AI21)),IF(AI21>0,N21/AI21,""),"") | AK21: {=IF(D21="","",IFERROR(MEDIAN(IF(($D$2:$D$401=D21)*ISNUMBER($R$2:$R$401),$R$2:$R$401)),""))} | AL21: =IF(ISNUMBER(AJ21),IF(AND(AJ21>=Resumen!$C$5,OR(NOT(ISNUMBER(R21)),NOT(ISNUMBER(AK21)),R21>=AK21)),"Ganador",IF(AJ21<=Resumen!$C$6,"Perdedor","Normal")),IF(ISNUMBER(AH21),IF(AH21>=Resumen!$C$5,"Ganador (7 d, provisional)",IF(AH21<=Resumen!$C$6,"Perdedor (7 d, provisional)","Normal (7 d, provisional)")),"")) | AM21: =IF(AND(ISNUMBER(Z21),ISNUMBER(N21)),IF(N21>0,Z21/N21*1000,""),"") | AN21: =IF(AND(ISNUMBER(U21),ISNUMBER(N21)),IF(N21>0,U21/N21*1000,""),"")
R22: =IF(AND(ISNUMBER(K22),ISNUMBER(Q22),K22>0),Q22/K22,"") | Y22: =IF(COUNT(V22:X22)=0,"",MAX(0,1-SUM(V22:X22))) | AF22: =IF(D22="","",COUNTIF($D$2:D22,D22)) | AG22: {=IF(D22="","",IFERROR(MEDIAN(IF(($D$2:$D$401=D22)*($AF$2:$AF$401>=AF22-5)*($AF$2:$AF$401<=AF22-1)*($M$2:$M$401<>""),$M$2:$M$401)),""))} | AH22: =IF(AND(ISNUMBER(M22),ISNUMBER(AG22)),IF(AG22>0,M22/AG22,""),"") | AI22: {=IF(D22="","",IFERROR(MEDIAN(IF(($D$2:$D$401=D22)*($AF$2:$AF$401>=AF22-5)*($AF$2:$AF$401<=AF22-1)*($N$2:$N$401<>""),$N$2:$N$401)),""))} | AJ22: =IF(AND(ISNUMBER(N22),ISNUMBER(AI22)),IF(AI22>0,N22/AI22,""),"") | AK22: {=IF(D22="","",IFERROR(MEDIAN(IF(($D$2:$D$401=D22)*ISNUMBER($R$2:$R$401),$R$2:$R$401)),""))} | AL22: =IF(ISNUMBER(AJ22),IF(AND(AJ22>=Resumen!$C$5,OR(NOT(ISNUMBER(R22)),NOT(ISNUMBER(AK22)),R22>=AK22)),"Ganador",IF(AJ22<=Resumen!$C$6,"Perdedor","Normal")),IF(ISNUMBER(AH22),IF(AH22>=Resumen!$C$5,"Ganador (7 d, provisional)",IF(AH22<=Resumen!$C$6,"Perdedor (7 d, provisional)","Normal (7 d, provisional)")),"")) | AM22: =IF(AND(ISNUMBER(Z22),ISNUMBER(N22)),IF(N22>0,Z22/N22*1000,""),"") | AN22: =IF(AND(ISNUMBER(U22),ISNUMBER(N22)),IF(N22>0,U22/N22*1000,""),"")
R23: =IF(AND(ISNUMBER(K23),ISNUMBER(Q23),K23>0),Q23/K23,"") | Y23: =IF(COUNT(V23:X23)=0,"",MAX(0,1-SUM(V23:X23))) | AF23: =IF(D23="","",COUNTIF($D$2:D23,D23)) | AG23: {=IF(D23="","",IFERROR(MEDIAN(IF(($D$2:$D$401=D23)*($AF$2:$AF$401>=AF23-5)*($AF$2:$AF$401<=AF23-1)*($M$2:$M$401<>""),$M$2:$M$401)),""))} | AH23: =IF(AND(ISNUMBER(M23),ISNUMBER(AG23)),IF(AG23>0,M23/AG23,""),"") | AI23: {=IF(D23="","",IFERROR(MEDIAN(IF(($D$2:$D$401=D23)*($AF$2:$AF$401>=AF23-5)*($AF$2:$AF$401<=AF23-1)*($N$2:$N$401<>""),$N$2:$N$401)),""))} | AJ23: =IF(AND(ISNUMBER(N23),ISNUMBER(AI23)),IF(AI23>0,N23/AI23,""),"") | AK23: {=IF(D23="","",IFERROR(MEDIAN(IF(($D$2:$D$401=D23)*ISNUMBER($R$2:$R$401),$R$2:$R$401)),""))} | AL23: =IF(ISNUMBER(AJ23),IF(AND(AJ23>=Resumen!$C$5,OR(NOT(ISNUMBER(R23)),NOT(ISNUMBER(AK23)),R23>=AK23)),"Ganador",IF(AJ23<=Resumen!$C$6,"Perdedor","Normal")),IF(ISNUMBER(AH23),IF(AH23>=Resumen!$C$5,"Ganador (7 d, provisional)",IF(AH23<=Resumen!$C$6,"Perdedor (7 d, provisional)","Normal (7 d, provisional)")),"")) | AM23: =IF(AND(ISNUMBER(Z23),ISNUMBER(N23)),IF(N23>0,Z23/N23*1000,""),"") | AN23: =IF(AND(ISNUMBER(U23),ISNUMBER(N23)),IF(N23>0,U23/N23*1000,""),"")
R24: =IF(AND(ISNUMBER(K24),ISNUMBER(Q24),K24>0),Q24/K24,"") | Y24: =IF(COUNT(V24:X24)=0,"",MAX(0,1-SUM(V24:X24))) | AF24: =IF(D24="","",COUNTIF($D$2:D24,D24)) | AG24: {=IF(D24="","",IFERROR(MEDIAN(IF(($D$2:$D$401=D24)*($AF$2:$AF$401>=AF24-5)*($AF$2:$AF$401<=AF24-1)*($M$2:$M$401<>""),$M$2:$M$401)),""))} | AH24: =IF(AND(ISNUMBER(M24),ISNUMBER(AG24)),IF(AG24>0,M24/AG24,""),"") | AI24: {=IF(D24="","",IFERROR(MEDIAN(IF(($D$2:$D$401=D24)*($AF$2:$AF$401>=AF24-5)*($AF$2:$AF$401<=AF24-1)*($N$2:$N$401<>""),$N$2:$N$401)),""))} | AJ24: =IF(AND(ISNUMBER(N24),ISNUMBER(AI24)),IF(AI24>0,N24/AI24,""),"") | AK24: {=IF(D24="","",IFERROR(MEDIAN(IF(($D$2:$D$401=D24)*ISNUMBER($R$2:$R$401),$R$2:$R$401)),""))} | AL24: =IF(ISNUMBER(AJ24),IF(AND(AJ24>=Resumen!$C$5,OR(NOT(ISNUMBER(R24)),NOT(ISNUMBER(AK24)),R24>=AK24)),"Ganador",IF(AJ24<=Resumen!$C$6,"Perdedor","Normal")),IF(ISNUMBER(AH24),IF(AH24>=Resumen!$C$5,"Ganador (7 d, provisional)",IF(AH24<=Resumen!$C$6,"Perdedor (7 d, provisional)","Normal (7 d, provisional)")),"")) | AM24: =IF(AND(ISNUMBER(Z24),ISNUMBER(N24)),IF(N24>0,Z24/N24*1000,""),"") | AN24: =IF(AND(ISNUMBER(U24),ISNUMBER(N24)),IF(N24>0,U24/N24*1000,""),"")
R25: =IF(AND(ISNUMBER(K25),ISNUMBER(Q25),K25>0),Q25/K25,"") | Y25: =IF(COUNT(V25:X25)=0,"",MAX(0,1-SUM(V25:X25))) | AF25: =IF(D25="","",COUNTIF($D$2:D25,D25)) | AG25: {=IF(D25="","",IFERROR(MEDIAN(IF(($D$2:$D$401=D25)*($AF$2:$AF$401>=AF25-5)*($AF$2:$AF$401<=AF25-1)*($M$2:$M$401<>""),$M$2:$M$401)),""))} | AH25: =IF(AND(ISNUMBER(M25),ISNUMBER(AG25)),IF(AG25>0,M25/AG25,""),"") | AI25: {=IF(D25="","",IFERROR(MEDIAN(IF(($D$2:$D$401=D25)*($AF$2:$AF$401>=AF25-5)*($AF$2:$AF$401<=AF25-1)*($N$2:$N$401<>""),$N$2:$N$401)),""))} | AJ25: =IF(AND(ISNUMBER(N25),ISNUMBER(AI25)),IF(AI25>0,N25/AI25,""),"") | AK25: {=IF(D25="","",IFERROR(MEDIAN(IF(($D$2:$D$401=D25)*ISNUMBER($R$2:$R$401),$R$2:$R$401)),""))} | AL25: =IF(ISNUMBER(AJ25),IF(AND(AJ25>=Resumen!$C$5,OR(NOT(ISNUMBER(R25)),NOT(ISNUMBER(AK25)),R25>=AK25)),"Ganador",IF(AJ25<=Resumen!$C$6,"Perdedor","Normal")),IF(ISNUMBER(AH25),IF(AH25>=Resumen!$C$5,"Ganador (7 d, provisional)",IF(AH25<=Resumen!$C$6,"Perdedor (7 d, provisional)","Normal (7 d, provisional)")),"")) | AM25: =IF(AND(ISNUMBER(Z25),ISNUMBER(N25)),IF(N25>0,Z25/N25*1000,""),"") | AN25: =IF(AND(ISNUMBER(U25),ISNUMBER(N25)),IF(N25>0,U25/N25*1000,""),"")
R26: =IF(AND(ISNUMBER(K26),ISNUMBER(Q26),K26>0),Q26/K26,"") | Y26: =IF(COUNT(V26:X26)=0,"",MAX(0,1-SUM(V26:X26))) | AF26: =IF(D26="","",COUNTIF($D$2:D26,D26)) | AG26: {=IF(D26="","",IFERROR(MEDIAN(IF(($D$2:$D$401=D26)*($AF$2:$AF$401>=AF26-5)*($AF$2:$AF$401<=AF26-1)*($M$2:$M$401<>""),$M$2:$M$401)),""))} | AH26: =IF(AND(ISNUMBER(M26),ISNUMBER(AG26)),IF(AG26>0,M26/AG26,""),"") | AI26: {=IF(D26="","",IFERROR(MEDIAN(IF(($D$2:$D$401=D26)*($AF$2:$AF$401>=AF26-5)*($AF$2:$AF$401<=AF26-1)*($N$2:$N$401<>""),$N$2:$N$401)),""))} | AJ26: =IF(AND(ISNUMBER(N26),ISNUMBER(AI26)),IF(AI26>0,N26/AI26,""),"") | AK26: {=IF(D26="","",IFERROR(MEDIAN(IF(($D$2:$D$401=D26)*ISNUMBER($R$2:$R$401),$R$2:$R$401)),""))} | AL26: =IF(ISNUMBER(AJ26),IF(AND(AJ26>=Resumen!$C$5,OR(NOT(ISNUMBER(R26)),NOT(ISNUMBER(AK26)),R26>=AK26)),"Ganador",IF(AJ26<=Resumen!$C$6,"Perdedor","Normal")),IF(ISNUMBER(AH26),IF(AH26>=Resumen!$C$5,"Ganador (7 d, provisional)",IF(AH26<=Resumen!$C$6,"Perdedor (7 d, provisional)","Normal (7 d, provisional)")),"")) | AM26: =IF(AND(ISNUMBER(Z26),ISNUMBER(N26)),IF(N26>0,Z26/N26*1000,""),"") | AN26: =IF(AND(ISNUMBER(U26),ISNUMBER(N26)),IF(N26>0,U26/N26*1000,""),"")
R27: =IF(AND(ISNUMBER(K27),ISNUMBER(Q27),K27>0),Q27/K27,"") | Y27: =IF(COUNT(V27:X27)=0,"",MAX(0,1-SUM(V27:X27))) | AF27: =IF(D27="","",COUNTIF($D$2:D27,D27)) | AG27: {=IF(D27="","",IFERROR(MEDIAN(IF(($D$2:$D$401=D27)*($AF$2:$AF$401>=AF27-5)*($AF$2:$AF$401<=AF27-1)*($M$2:$M$401<>""),$M$2:$M$401)),""))} | AH27: =IF(AND(ISNUMBER(M27),ISNUMBER(AG27)),IF(AG27>0,M27/AG27,""),"") | AI27: {=IF(D27="","",IFERROR(MEDIAN(IF(($D$2:$D$401=D27)*($AF$2:$AF$401>=AF27-5)*($AF$2:$AF$401<=AF27-1)*($N$2:$N$401<>""),$N$2:$N$401)),""))} | AJ27: =IF(AND(ISNUMBER(N27),ISNUMBER(AI27)),IF(AI27>0,N27/AI27,""),"") | AK27: {=IF(D27="","",IFERROR(MEDIAN(IF(($D$2:$D$401=D27)*ISNUMBER($R$2:$R$401),$R$2:$R$401)),""))} | AL27: =IF(ISNUMBER(AJ27),IF(AND(AJ27>=Resumen!$C$5,OR(NOT(ISNUMBER(R27)),NOT(ISNUMBER(AK27)),R27>=AK27)),"Ganador",IF(AJ27<=Resumen!$C$6,"Perdedor","Normal")),IF(ISNUMBER(AH27),IF(AH27>=Resumen!$C$5,"Ganador (7 d, provisional)",IF(AH27<=Resumen!$C$6,"Perdedor (7 d, provisional)","Normal (7 d, provisional)")),"")) | AM27: =IF(AND(ISNUMBER(Z27),ISNUMBER(N27)),IF(N27>0,Z27/N27*1000,""),"") | AN27: =IF(AND(ISNUMBER(U27),ISNUMBER(N27)),IF(N27>0,U27/N27*1000,""),"")
R28: =IF(AND(ISNUMBER(K28),ISNUMBER(Q28),K28>0),Q28/K28,"") | Y28: =IF(COUNT(V28:X28)=0,"",MAX(0,1-SUM(V28:X28))) | AF28: =IF(D28="","",COUNTIF($D$2:D28,D28)) | AG28: {=IF(D28="","",IFERROR(MEDIAN(IF(($D$2:$D$401=D28)*($AF$2:$AF$401>=AF28-5)*($AF$2:$AF$401<=AF28-1)*($M$2:$M$401<>""),$M$2:$M$401)),""))} | AH28: =IF(AND(ISNUMBER(M28),ISNUMBER(AG28)),IF(AG28>0,M28/AG28,""),"") | AI28: {=IF(D28="","",IFERROR(MEDIAN(IF(($D$2:$D$401=D28)*($AF$2:$AF$401>=AF28-5)*($AF$2:$AF$401<=AF28-1)*($N$2:$N$401<>""),$N$2:$N$401)),""))} | AJ28: =IF(AND(ISNUMBER(N28),ISNUMBER(AI28)),IF(AI28>0,N28/AI28,""),"") | AK28: {=IF(D28="","",IFERROR(MEDIAN(IF(($D$2:$D$401=D28)*ISNUMBER($R$2:$R$401),$R$2:$R$401)),""))} | AL28: =IF(ISNUMBER(AJ28),IF(AND(AJ28>=Resumen!$C$5,OR(NOT(ISNUMBER(R28)),NOT(ISNUMBER(AK28)),R28>=AK28)),"Ganador",IF(AJ28<=Resumen!$C$6,"Perdedor","Normal")),IF(ISNUMBER(AH28),IF(AH28>=Resumen!$C$5,"Ganador (7 d, provisional)",IF(AH28<=Resumen!$C$6,"Perdedor (7 d, provisional)","Normal (7 d, provisional)")),"")) | AM28: =IF(AND(ISNUMBER(Z28),ISNUMBER(N28)),IF(N28>0,Z28/N28*1000,""),"") | AN28: =IF(AND(ISNUMBER(U28),ISNUMBER(N28)),IF(N28>0,U28/N28*1000,""),"")
R29: =IF(AND(ISNUMBER(K29),ISNUMBER(Q29),K29>0),Q29/K29,"") | Y29: =IF(COUNT(V29:X29)=0,"",MAX(0,1-SUM(V29:X29))) | AF29: =IF(D29="","",COUNTIF($D$2:D29,D29)) | AG29: {=IF(D29="","",IFERROR(MEDIAN(IF(($D$2:$D$401=D29)*($AF$2:$AF$401>=AF29-5)*($AF$2:$AF$401<=AF29-1)*($M$2:$M$401<>""),$M$2:$M$401)),""))} | AH29: =IF(AND(ISNUMBER(M29),ISNUMBER(AG29)),IF(AG29>0,M29/AG29,""),"") | AI29: {=IF(D29="","",IFERROR(MEDIAN(IF(($D$2:$D$401=D29)*($AF$2:$AF$401>=AF29-5)*($AF$2:$AF$401<=AF29-1)*($N$2:$N$401<>""),$N$2:$N$401)),""))} | AJ29: =IF(AND(ISNUMBER(N29),ISNUMBER(AI29)),IF(AI29>0,N29/AI29,""),"") | AK29: {=IF(D29="","",IFERROR(MEDIAN(IF(($D$2:$D$401=D29)*ISNUMBER($R$2:$R$401),$R$2:$R$401)),""))} | AL29: =IF(ISNUMBER(AJ29),IF(AND(AJ29>=Resumen!$C$5,OR(NOT(ISNUMBER(R29)),NOT(ISNUMBER(AK29)),R29>=AK29)),"Ganador",IF(AJ29<=Resumen!$C$6,"Perdedor","Normal")),IF(ISNUMBER(AH29),IF(AH29>=Resumen!$C$5,"Ganador (7 d, provisional)",IF(AH29<=Resumen!$C$6,"Perdedor (7 d, provisional)","Normal (7 d, provisional)")),"")) | AM29: =IF(AND(ISNUMBER(Z29),ISNUMBER(N29)),IF(N29>0,Z29/N29*1000,""),"") | AN29: =IF(AND(ISNUMBER(U29),ISNUMBER(N29)),IF(N29>0,U29/N29*1000,""),"")
R30: =IF(AND(ISNUMBER(K30),ISNUMBER(Q30),K30>0),Q30/K30,"") | Y30: =IF(COUNT(V30:X30)=0,"",MAX(0,1-SUM(V30:X30))) | AF30: =IF(D30="","",COUNTIF($D$2:D30,D30)) | AG30: {=IF(D30="","",IFERROR(MEDIAN(IF(($D$2:$D$401=D30)*($AF$2:$AF$401>=AF30-5)*($AF$2:$AF$401<=AF30-1)*($M$2:$M$401<>""),$M$2:$M$401)),""))} | AH30: =IF(AND(ISNUMBER(M30),ISNUMBER(AG30)),IF(AG30>0,M30/AG30,""),"") | AI30: {=IF(D30="","",IFERROR(MEDIAN(IF(($D$2:$D$401=D30)*($AF$2:$AF$401>=AF30-5)*($AF$2:$AF$401<=AF30-1)*($N$2:$N$401<>""),$N$2:$N$401)),""))} | AJ30: =IF(AND(ISNUMBER(N30),ISNUMBER(AI30)),IF(AI30>0,N30/AI30,""),"") | AK30: {=IF(D30="","",IFERROR(MEDIAN(IF(($D$2:$D$401=D30)*ISNUMBER($R$2:$R$401),$R$2:$R$401)),""))} | AL30: =IF(ISNUMBER(AJ30),IF(AND(AJ30>=Resumen!$C$5,OR(NOT(ISNUMBER(R30)),NOT(ISNUMBER(AK30)),R30>=AK30)),"Ganador",IF(AJ30<=Resumen!$C$6,"Perdedor","Normal")),IF(ISNUMBER(AH30),IF(AH30>=Resumen!$C$5,"Ganador (7 d, provisional)",IF(AH30<=Resumen!$C$6,"Perdedor (7 d, provisional)","Normal (7 d, provisional)")),"")) | AM30: =IF(AND(ISNUMBER(Z30),ISNUMBER(N30)),IF(N30>0,Z30/N30*1000,""),"") | AN30: =IF(AND(ISNUMBER(U30),ISNUMBER(N30)),IF(N30>0,U30/N30*1000,""),"")
R31: =IF(AND(ISNUMBER(K31),ISNUMBER(Q31),K31>0),Q31/K31,"") | Y31: =IF(COUNT(V31:X31)=0,"",MAX(0,1-SUM(V31:X31))) | AF31: =IF(D31="","",COUNTIF($D$2:D31,D31)) | AG31: {=IF(D31="","",IFERROR(MEDIAN(IF(($D$2:$D$401=D31)*($AF$2:$AF$401>=AF31-5)*($AF$2:$AF$401<=AF31-1)*($M$2:$M$401<>""),$M$2:$M$401)),""))} | AH31: =IF(AND(ISNUMBER(M31),ISNUMBER(AG31)),IF(AG31>0,M31/AG31,""),"") | AI31: {=IF(D31="","",IFERROR(MEDIAN(IF(($D$2:$D$401=D31)*($AF$2:$AF$401>=AF31-5)*($AF$2:$AF$401<=AF31-1)*($N$2:$N$401<>""),$N$2:$N$401)),""))} | AJ31: =IF(AND(ISNUMBER(N31),ISNUMBER(AI31)),IF(AI31>0,N31/AI31,""),"") | AK31: {=IF(D31="","",IFERROR(MEDIAN(IF(($D$2:$D$401=D31)*ISNUMBER($R$2:$R$401),$R$2:$R$401)),""))} | AL31: =IF(ISNUMBER(AJ31),IF(AND(AJ31>=Resumen!$C$5,OR(NOT(ISNUMBER(R31)),NOT(ISNUMBER(AK31)),R31>=AK31)),"Ganador",IF(AJ31<=Resumen!$C$6,"Perdedor","Normal")),IF(ISNUMBER(AH31),IF(AH31>=Resumen!$C$5,"Ganador (7 d, provisional)",IF(AH31<=Resumen!$C$6,"Perdedor (7 d, provisional)","Normal (7 d, provisional)")),"")) | AM31: =IF(AND(ISNUMBER(Z31),ISNUMBER(N31)),IF(N31>0,Z31/N31*1000,""),"") | AN31: =IF(AND(ISNUMBER(U31),ISNUMBER(N31)),IF(N31>0,U31/N31*1000,""),"")
R32: =IF(AND(ISNUMBER(K32),ISNUMBER(Q32),K32>0),Q32/K32,"") | Y32: =IF(COUNT(V32:X32)=0,"",MAX(0,1-SUM(V32:X32))) | AF32: =IF(D32="","",COUNTIF($D$2:D32,D32)) | AG32: {=IF(D32="","",IFERROR(MEDIAN(IF(($D$2:$D$401=D32)*($AF$2:$AF$401>=AF32-5)*($AF$2:$AF$401<=AF32-1)*($M$2:$M$401<>""),$M$2:$M$401)),""))} | AH32: =IF(AND(ISNUMBER(M32),ISNUMBER(AG32)),IF(AG32>0,M32/AG32,""),"") | AI32: {=IF(D32="","",IFERROR(MEDIAN(IF(($D$2:$D$401=D32)*($AF$2:$AF$401>=AF32-5)*($AF$2:$AF$401<=AF32-1)*($N$2:$N$401<>""),$N$2:$N$401)),""))} | AJ32: =IF(AND(ISNUMBER(N32),ISNUMBER(AI32)),IF(AI32>0,N32/AI32,""),"") | AK32: {=IF(D32="","",IFERROR(MEDIAN(IF(($D$2:$D$401=D32)*ISNUMBER($R$2:$R$401),$R$2:$R$401)),""))} | AL32: =IF(ISNUMBER(AJ32),IF(AND(AJ32>=Resumen!$C$5,OR(NOT(ISNUMBER(R32)),NOT(ISNUMBER(AK32)),R32>=AK32)),"Ganador",IF(AJ32<=Resumen!$C$6,"Perdedor","Normal")),IF(ISNUMBER(AH32),IF(AH32>=Resumen!$C$5,"Ganador (7 d, provisional)",IF(AH32<=Resumen!$C$6,"Perdedor (7 d, provisional)","Normal (7 d, provisional)")),"")) | AM32: =IF(AND(ISNUMBER(Z32),ISNUMBER(N32)),IF(N32>0,Z32/N32*1000,""),"") | AN32: =IF(AND(ISNUMBER(U32),ISNUMBER(N32)),IF(N32>0,U32/N32*1000,""),"")
... R401: =IF(AND(ISNUMBER(K401),ISNUMBER(Q401),K401>0),Q401/K401,"") | Y401: =IF(COUNT(V401:X401)=0,"",MAX(0,1-SUM(V401:X401))) | AF401: =IF(D401="","",COUNTIF($D$2:D401,D401)) | AG401: {=IF(D401="","",IFERROR(MEDIAN(IF(($D$2:$D$401=D401)*($AF$2:$AF$401>=AF401-5)*($AF$2:$AF$401<=AF401-1)*($M$2:$M$401<>""),$M$2:$M$401)),""))} | AH401: =IF(AND(ISNUMBER(M401),ISNUMBER(AG401)),IF(AG401>0,M401/AG401,""),"") | AI401: {=IF(D401="","",IFERROR(MEDIAN(IF(($D$2:$D$401=D401)*($AF$2:$AF$401>=AF401-5)*($AF$2:$AF$401<=AF401-1)*($N$2:$N$401<>""),$N$2:$N$401)),""))} | AJ401: =IF(AND(ISNUMBER(N401),ISNUMBER(AI401)),IF(AI401>0,N401/AI401,""),"") | AK401: {=IF(D401="","",IFERROR(MEDIAN(IF(($D$2:$D$401=D401)*ISNUMBER($R$2:$R$401),$R$2:$R$401)),""))} | AL401: =IF(ISNUMBER(AJ401),IF(AND(AJ401>=Resumen!$C$5,OR(NOT(ISNUMBER(R401)),NOT(ISNUMBER(AK401)),R401>=AK401)),"Ganador",IF(AJ401<=Resumen!$C$6,"Perdedor","Normal")),IF(ISNUMBER(AH401),IF(AH401>=Resumen!$C$5,"Ganador (7 d, provisional)",IF(AH401<=Resumen!$C$6,"Perdedor (7 d, provisional)","Normal (7 d, provisional)")),"")) | AM401: =IF(AND(ISNUMBER(Z401),ISNUMBER(N401)),IF(N401>0,Z401/N401*1000,""),"") | AN401: =IF(AND(ISNUMBER(U401),ISNUMBER(N401)),IF(N401>0,U401/N401*1000,""),"")

Sheet Ideas
A1: id | B1: pilar | C1: tema | D1: keyword_principal | E1: evidencia_demanda | F1: demanda | G1: curiosidad | H1: encaje_promesa | I1: evidencia_fuentes | J1: diferenciacion | K1: apta_anunciantes | L1: shorts_serie | M1: costo_bajo | N1: total_100 | O1: decision | P1: estado | Q1: video_id
A2: PESOS | E2: Pesos de la fase 8 (suman 100). Puedes cambiarlos: los totales se recalculan. | F2: 20 | G2: 15 | H2: 15 | I2: 15 | J2: 10 | K2: 10 | L2: 5 | M2: 10 | N2: =SUM(F2:M2) -> 100
A3: I01 | B3: P1 | C3: La verdadera historia de La Llorona | D3: la verdadera historia de la llorona | E3: Autocompletado MX/CO/AR; 'mitos y leyendas' 53.300 (comp. 42); 'leyendas mexicanas' 22.300 (+125 %) | F3: 5 | G3: 5 | H3: 5 | I3: 4 | J3: 3 | K3: 3 | L3: 5 | M3: 4 | N3: =SUMPRODUCT(F3:M3,$F$2:$M$2)/5 -> 87 | O3: =IF(N3>=75,"producir pronto",IF(N3>=60,"banco","reformular o descartar")) -> producir pronto | P3: planificado | Q3: L1
A4: I02 | B4: P2 | C4: ¿Por qué Colombia se llama Colombia? | D4: historia de colombia | E4: 'historia de colombia' 40.400 (comp. 46, +142 %); la pregunta exacta sin medir | F4: 4 | G4: 4 | H4: 4 | I4: 5 | J4: 4 | K4: 5 | L4: 4 | M4: 4 | N4: =SUMPRODUCT(F4:M4,$F$2:$M$2)/5 -> 85 | O4: =IF(N4>=75,"producir pronto",IF(N4>=60,"banco","reformular o descartar")) -> producir pronto | P4: planificado | Q4: L2
A5: I04 | B5: P1 | C5: El Dorado: lo que sí existió | D5: el dorado leyenda | E5: Sin medir (pendiente de vidIQ en noviembre) | F5: 3 | G5: 5 | H5: 5 | I5: 5 | J5: 3 | K5: 5 | L5: 4 | M5: 3 | N5: =SUMPRODUCT(F5:M5,$F$2:$M$2)/5 -> 83 | O5: =IF(N5>=75,"producir pronto",IF(N5>=60,"banco","reformular o descartar")) -> producir pronto | P5: planificado | Q5: L3
A6: I07 | B6: P1 | C6: El chupacabras: cómo nació un monstruo moderno | D6: la leyenda del chupacabras | E6: Autocompletado MX/CO 'la leyenda del chupacabras' | F6: 4 | G6: 4 | H6: 5 | I6: 4 | J6: 3 | K6: 4 | L6: 5 | M6: 4 | N6: =SUMPRODUCT(F6:M6,$F$2:$M$2)/5 -> 82 | O6: =IF(N6>=75,"producir pronto",IF(N6>=60,"banco","reformular o descartar")) -> producir pronto | P6: planificado | Q6: L4
A7: I05 | B7: P2 | C7: ¿De verdad unos cientos de españoles conquistaron a los mexicas? | D7: conquista de mexico | E7: 'hernan cortes' 26.200 (comp. 59); autocompletado 'porque los españoles conquistaron mexico' | F7: 4 | G7: 5 | H7: 5 | I7: 5 | J7: 3 | K7: 3 | L7: 4 | M7: 2 | N7: =SUMPRODUCT(F7:M7,$F$2:$M$2)/5 -> 81 | O7: =IF(N7>=75,"producir pronto",IF(N7>=60,"banco","reformular o descartar")) -> producir pronto | P7: planificado | Q7: L5
A8: I10 | B8: P2 | C8: ¿Por qué Panamá dejó de ser parte de Colombia? | D8: historia de colombia | E8: 'historia de colombia' 40.400; la pregunta exacta sin medir | F8: 3 | G8: 5 | H8: 4 | I8: 5 | J8: 3 | K8: 5 | L8: 4 | M8: 3 | N8: =SUMPRODUCT(F8:M8,$F$2:$M$2)/5 -> 80 | O8: =IF(N8>=75,"producir pronto",IF(N8>=60,"banco","reformular o descartar")) -> producir pronto | P8: pendiente
A9: I09 | B9: P2 | C9: ¿Por qué la capital de México está sobre un lago? | D9: historia de mexico | E9: 'historia de mexico' 58.900 (comp. 60, +141 %); la pregunta exacta sin medir | F9: 4 | G9: 4 | H9: 3 | I9: 5 | J9: 3 | K9: 5 | L9: 4 | M9: 3 | N9: =SUMPRODUCT(F9:M9,$F$2:$M$2)/5 -> 78 | O9: =IF(N9>=75,"producir pronto",IF(N9>=60,"banco","reformular o descartar")) -> producir pronto | P9: planificado | Q9: L6
A10: I08 | B10: P1 | C10: Las momias de Guanajuato: la historia real | D10: momias de guanajuato | E10: Autocompletado MX/CO/AR 'la leyenda de las momias de guanajuato' | F10: 4 | G10: 5 | H10: 4 | I10: 4 | J10: 3 | K10: 2 | L10: 4 | M10: 3 | N10: =SUMPRODUCT(F10:M10,$F$2:$M$2)/5 -> 75 | O10: =IF(N10>=75,"producir pronto",IF(N10>=60,"banco","reformular o descartar")) -> producir pronto | P10: pendiente
A11: I13 | B11: P2 | C11: ¿Por qué los incas no escribían? (los quipus) | D11: los incas | E11: Autocompletado 'los incas' (mezclado con música y 'para niños') | F11: 3 | G11: 4 | H11: 4 | I11: 4 | J11: 3 | K11: 5 | L11: 4 | M11: 3 | N11: =SUMPRODUCT(F11:M11,$F$2:$M$2)/5 -> 74 | O11: =IF(N11>=75,"producir pronto",IF(N11>=60,"banco","reformular o descartar")) -> banco | P11: pendiente
A12: I03 | B12: P3 | C12: Así vivías si nacías en Tenochtitlan | D12: como vivian los aztecas | E12: 'como vivian los aztecas' 4.500 (comp. 40); 'tenochtitlan' 21.500; 'los aztecas' 24.200 (+161 %) | F12: 4 | G12: 3 | H12: 3 | I12: 5 | J12: 3 | K12: 4 | L12: 4 | M12: 2 | N12: =SUMPRODUCT(F12:M12,$F$2:$M$2)/5 -> 71 | O12: =IF(N12>=75,"producir pronto",IF(N12>=60,"banco","reformular o descartar")) -> banco | P12: pendiente
A13: I06 | B13: P4 | C13: Una leyenda de cada país de Latinoamérica | D13: leyendas de cada pais | E13: Autocompletado 'leyendas de cada país' (+ 'de latam', Perú, Honduras, el Silbón) | F13: 4 | G13: 4 | H13: 3 | I13: 3 | J13: 3 | K13: 3 | L13: 5 | M13: 2 | N13: =SUMPRODUCT(F13:M13,$F$2:$M$2)/5 -> 67 | O13: =IF(N13>=75,"producir pronto",IF(N13>=60,"banco","reformular o descartar")) -> banco | P13: pendiente
A14: I14 | B14: P3 | C14: Así vivías en la Nueva España | D14: como era la vida en la nueva españa | E14: Autocompletado MX 'como era la vida en la nueva españa' | F14: 3 | G14: 3 | H14: 3 | I14: 4 | J14: 3 | K14: 4 | L14: 3 | M14: 3 | N14: =SUMPRODUCT(F14:M14,$F$2:$M$2)/5 -> 65 | O14: =IF(N14>=75,"producir pronto",IF(N14>=60,"banco","reformular o descartar")) -> banco | P14: pendiente
A15: I11 | B15: P1 | C15: El Silbón: de dónde sale la leyenda | D15: la leyenda del silbon | E15: Autocompletado CO 'la leyenda del silbón'; 'leyendas de cada país el silbón' | F15: 3 | G15: 4 | H15: 3 | I15: 2 | J15: 3 | K15: 3 | L15: 4 | M15: 4 | N15: =SUMPRODUCT(F15:M15,$F$2:$M$2)/5 -> 63 | O15: =IF(N15>=75,"producir pronto",IF(N15>=60,"banco","reformular o descartar")) -> banco | P15: pendiente
A16: I12 | B16: P1 | C16: La Patasola, el Mohán y la Madremonte | D16: leyendas de colombia | E16: Autocompletado 'leyendas de colombia la patasola' | F16: 3 | G16: 3 | H16: 3 | I16: 2 | J16: 3 | K16: 3 | L16: 5 | M16: 3 | N16: =SUMPRODUCT(F16:M16,$F$2:$M$2)/5 -> 59 | O16: =IF(N16>=75,"producir pronto",IF(N16>=60,"banco","reformular o descartar")) -> reformular o descartar | P16: pendiente
A17: I15 | B17: P1 | C17: La Nahuala | D17: la leyenda de la nahuala | E17: Autocompletado MX/CO/AR, pero la intención es la película animada de 2007 | F17: 4 | G17: 3 | H17: 2 | I17: 2 | J17: 2 | K17: 3 | L17: 3 | M17: 3 | N17: =SUMPRODUCT(F17:M17,$F$2:$M$2)/5 -> 56 | O17: =IF(N17>=75,"producir pronto",IF(N17>=60,"banco","reformular o descartar")) -> reformular o descartar | P17: pendiente
A18: I16 | B18: P1 | C18: El Charro Negro | D18: la leyenda del charro negro | E18: Autocompletado MX/CO/AR, pero dominado por la película animada de 2018 | F18: 4 | G18: 3 | H18: 2 | I18: 2 | J18: 2 | K18: 3 | L18: 3 | M18: 3 | N18: =SUMPRODUCT(F18:M18,$F$2:$M$2)/5 -> 56 | O18: =IF(N18>=75,"producir pronto",IF(N18>=60,"banco","reformular o descartar")) -> reformular o descartar | P18: pendiente
N19: =IF(COUNT(F19:M19)=0,"",SUMPRODUCT(F19:M19,$F$2:$M$2)/5) | O19: =IF(N19="","",IF(N19>=75,"producir pronto",IF(N19>=60,"banco","reformular o descartar")))
N20: =IF(COUNT(F20:M20)=0,"",SUMPRODUCT(F20:M20,$F$2:$M$2)/5) | O20: =IF(N20="","",IF(N20>=75,"producir pronto",IF(N20>=60,"banco","reformular o descartar")))
N21: =IF(COUNT(F21:M21)=0,"",SUMPRODUCT(F21:M21,$F$2:$M$2)/5) | O21: =IF(N21="","",IF(N21>=75,"producir pronto",IF(N21>=60,"banco","reformular o descartar")))
N22: =IF(COUNT(F22:M22)=0,"",SUMPRODUCT(F22:M22,$F$2:$M$2)/5) | O22: =IF(N22="","",IF(N22>=75,"producir pronto",IF(N22>=60,"banco","reformular o descartar")))
N23: =IF(COUNT(F23:M23)=0,"",SUMPRODUCT(F23:M23,$F$2:$M$2)/5) | O23: =IF(N23="","",IF(N23>=75,"producir pronto",IF(N23>=60,"banco","reformular o descartar")))
N24: =IF(COUNT(F24:M24)=0,"",SUMPRODUCT(F24:M24,$F$2:$M$2)/5) | O24: =IF(N24="","",IF(N24>=75,"producir pronto",IF(N24>=60,"banco","reformular o descartar")))
N25: =IF(COUNT(F25:M25)=0,"",SUMPRODUCT(F25:M25,$F$2:$M$2)/5) | O25: =IF(N25="","",IF(N25>=75,"producir pronto",IF(N25>=60,"banco","reformular o descartar")))
N26: =IF(COUNT(F26:M26)=0,"",SUMPRODUCT(F26:M26,$F$2:$M$2)/5) | O26: =IF(N26="","",IF(N26>=75,"producir pronto",IF(N26>=60,"banco","reformular o descartar")))
N27: =IF(COUNT(F27:M27)=0,"",SUMPRODUCT(F27:M27,$F$2:$M$2)/5) | O27: =IF(N27="","",IF(N27>=75,"producir pronto",IF(N27>=60,"banco","reformular o descartar")))
N28: =IF(COUNT(F28:M28)=0,"",SUMPRODUCT(F28:M28,$F$2:$M$2)/5) | O28: =IF(N28="","",IF(N28>=75,"producir pronto",IF(N28>=60,"banco","reformular o descartar")))
N29: =IF(COUNT(F29:M29)=0,"",SUMPRODUCT(F29:M29,$F$2:$M$2)/5) | O29: =IF(N29="","",IF(N29>=75,"producir pronto",IF(N29>=60,"banco","reformular o descartar")))
N30: =IF(COUNT(F30:M30)=0,"",SUMPRODUCT(F30:M30,$F$2:$M$2)/5) | O30: =IF(N30="","",IF(N30>=75,"producir pronto",IF(N30>=60,"banco","reformular o descartar")))
... N58: =IF(COUNT(F58:M58)=0,"",SUMPRODUCT(F58:M58,$F$2:$M$2)/5) | O58: =IF(N58="","",IF(N58>=75,"producir pronto",IF(N58>=60,"banco","reformular o descartar")))

Sheet Experimentos
A1: id | B1: fecha_inicio | C1: video_id | D1: tipo | E1: regla_que_se_prueba | F1: hipotesis | G1: variante_A | H1: variante_B | I1: variante_C | J1: metrica_de_decision | K1: resultado | L1: dato_resultado | M1: conclusion | N1: victorias_de_la_regla | O1: estado_de_la_regla
A2: H1 | B2: 46345 | C2: L1 | D2: A/B miniatura | E2: pregunta en miniatura | F2: La miniatura con pregunta (¿EXISTIÓ?) gana a la de afirmación (ANTES DE 1519) en tiempo de visualización | G2: ¿EXISTIÓ? | H2: ANTES DE 1519 | I2: LO DICE AQUÍ | J2: Resultado de Prueba y compara (tiempo de visualización) | N2: =IF(E2="","",COUNTIFS($E$2:$E$201,E2,$K$2:$K$201,"Winner")) -> 0 | O2: =IF(E2="","",IF(N2>=3,"Norma del canal",IF(N2>=1,"Hipótesis con 1-2 victorias","Hipótesis"))) -> Hipótesis
A3: H2 | B3: 46359 | C3: L2 | D3: Pilar | E3: P2 trae más búsqueda | F3: Un '¿Por qué…?' de identidad nacional (P2) consigue más tráfico de búsqueda que una leyenda (P1) | G3: L2 (P2) | H3: L1 (P1) | J3: trafico_busqueda a 7 días | N3: =IF(E3="","",COUNTIFS($E$2:$E$201,E3,$K$2:$K$201,"Winner")) -> 0 | O3: =IF(E3="","",IF(N3>=3,"Norma del canal",IF(N3>=1,"Hipótesis con 1-2 victorias","Hipótesis"))) -> Hipótesis
A4: H3 | B4: 46373 | C4: L3 | D4: A/B título | E4: título contraintuitivo | F4: El título contraintuitivo ('sí existió, pero no era una ciudad') gana a 'Lo que es verdad de El Dorado' | G4: El Dorado sí existió (pero no era una ciudad) | H4: Lo que es verdad de El Dorado | J4: Resultado de Prueba y compara | N4: =IF(E4="","",COUNTIFS($E$2:$E$201,E4,$K$2:$K$201,"Winner")) -> 0 | O4: =IF(E4="","",IF(N4>=3,"Norma del canal",IF(N4>=1,"Hipótesis con 1-2 victorias","Hipótesis"))) -> Hipótesis
A5: H4 | B5: 46386 | C5: L4 | D5: Tema | E5: leyenda moderna con fecha | F5: Una leyenda moderna con fecha (1995) retiene más que una antigua (La Llorona) | G5: L4 | H5: L1 | J5: avd_min y pct_visto a 28 días | N5: =IF(E5="","",COUNTIFS($E$2:$E$201,E5,$K$2:$K$201,"Winner")) -> 0 | O5: =IF(E5="","",IF(N5>=3,"Norma del canal",IF(N5>=1,"Hipótesis con 1-2 victorias","Hipótesis"))) -> Hipótesis
A6: H5 | B6: 46401 | C6: L5 | D6: Tema | E6: debate sin polarización | F6: Un tema de debate tiene más comentarios sin pasar a la polarización | G6: L5 | H6: mediana de largos anteriores | J6: Comentarios por 1.000 vistas y comentarios moderados | N6: =IF(E6="","",COUNTIFS($E$2:$E$201,E6,$K$2:$K$201,"Winner")) -> 0 | O6: =IF(E6="","",IF(N6>=3,"Norma del canal",IF(N6>=1,"Hipótesis con 1-2 victorias","Hipótesis"))) -> Hipótesis
N7: =IF(E7="","",COUNTIFS($E$2:$E$201,E7,$K$2:$K$201,"Winner")) | O7: =IF(E7="","",IF(N7>=3,"Norma del canal",IF(N7>=1,"Hipótesis con 1-2 victorias","Hipótesis")))
N8: =IF(E8="","",COUNTIFS($E$2:$E$201,E8,$K$2:$K$201,"Winner")) | O8: =IF(E8="","",IF(N8>=3,"Norma del canal",IF(N8>=1,"Hipótesis con 1-2 victorias","Hipótesis")))
N9: =IF(E9="","",COUNTIFS($E$2:$E$201,E9,$K$2:$K$201,"Winner")) | O9: =IF(E9="","",IF(N9>=3,"Norma del canal",IF(N9>=1,"Hipótesis con 1-2 victorias","Hipótesis")))
N10: =IF(E10="","",COUNTIFS($E$2:$E$201,E10,$K$2:$K$201,"Winner")) | O10: =IF(E10="","",IF(N10>=3,"Norma del canal",IF(N10>=1,"Hipótesis con 1-2 victorias","Hipótesis")))
N11: =IF(E11="","",COUNTIFS($E$2:$E$201,E11,$K$2:$K$201,"Winner")) | O11: =IF(E11="","",IF(N11>=3,"Norma del canal",IF(N11>=1,"Hipótesis con 1-2 victorias","Hipótesis")))
N12: =IF(E12="","",COUNTIFS($E$2:$E$201,E12,$K$2:$K$201,"Winner")) | O12: =IF(E12="","",IF(N12>=3,"Norma del canal",IF(N12>=1,"Hipótesis con 1-2 victorias","Hipótesis")))
N13: =IF(E13="","",COUNTIFS($E$2:$E$201,E13,$K$2:$K$201,"Winner")) | O13: =IF(E13="","",IF(N13>=3,"Norma del canal",IF(N13>=1,"Hipótesis con 1-2 victorias","Hipótesis")))
N14: =IF(E14="","",COUNTIFS($E$2:$E$201,E14,$K$2:$K$201,"Winner")) | O14: =IF(E14="","",IF(N14>=3,"Norma del canal",IF(N14>=1,"Hipótesis con 1-2 victorias","Hipótesis")))
N15: =IF(E15="","",COUNTIFS($E$2:$E$201,E15,$K$2:$K$201,"Winner")) | O15: =IF(E15="","",IF(N15>=3,"Norma del canal",IF(N15>=1,"Hipótesis con 1-2 victorias","Hipótesis")))
N16: =IF(E16="","",COUNTIFS($E$2:$E$201,E16,$K$2:$K$201,"Winner")) | O16: =IF(E16="","",IF(N16>=3,"Norma del canal",IF(N16>=1,"Hipótesis con 1-2 victorias","Hipótesis")))
N17: =IF(E17="","",COUNTIFS($E$2:$E$201,E17,$K$2:$K$201,"Winner")) | O17: =IF(E17="","",IF(N17>=3,"Norma del canal",IF(N17>=1,"Hipótesis con 1-2 victorias","Hipótesis")))
N18: =IF(E18="","",COUNTIFS($E$2:$E$201,E18,$K$2:$K$201,"Winner")) | O18: =IF(E18="","",IF(N18>=3,"Norma del canal",IF(N18>=1,"Hipótesis con 1-2 victorias","Hipótesis")))
... N201: =IF(E201="","",COUNTIFS($E$2:$E$201,E201,$K$2:$K$201,"Winner")) | O201: =IF(E201="","",IF(N201>=3,"Norma del canal",IF(N201>=1,"Hipótesis con 1-2 victorias","Hipótesis")))

Sheet Resumen
B1: Resumen del canal
B2: Celdas amarillas: las rellenas tú con datos de YouTube Studio. El resto se calcula solo.
B4: Parámetros
B5: Umbral de ganador (múltiplo a 28 días ≥) | C5: 1.5 | G5: Fase 12. Mismo criterio de rendimiento relativo de la fase 1.
B6: Umbral de perdedor (múltiplo a 28 días ≤) | C6: 0.67 | G6: Inverso de 1,5.
B8: Producción y alcance (suma de las cifras a 28 días de cada video)
C9: Largos | D9: Shorts
B10: Videos publicados (con URL) | C10: =COUNTIFS(Videos!$D$2:$D$401,"Largo",Videos!$J$2:$J$401,"<>") -> 0 | D10: =COUNTIFS(Videos!$D$2:$D$401,"Short",Videos!$J$2:$J$401,"<>") -> 0
B11: Vistas a 28 días (suma) | C11: =SUMIFS(Videos!$N$2:$N$401,Videos!$D$2:$D$401,"Largo") -> 0 | D11: =SUMIFS(Videos!$N$2:$N$401,Videos!$D$2:$D$401,"Short") -> 0
B12: Horas vistas a 28 días (suma) | C12: =SUMIFS(Videos!$T$2:$T$401,Videos!$D$2:$D$401,"Largo") -> 0 | D12: =SUMIFS(Videos!$T$2:$T$401,Videos!$D$2:$D$401,"Short") -> 0
B13: Suscriptores ganados a 28 días (suma) | C13: =SUMIFS(Videos!$U$2:$U$401,Videos!$D$2:$D$401,"Largo") -> 0 | D13: =SUMIFS(Videos!$U$2:$U$401,Videos!$D$2:$D$401,"Short") -> 0
B14: Horas de producción medias por video | C14: =IFERROR(AVERAGEIFS(Videos!$AA$2:$AA$401,Videos!$D$2:$D$401,"Largo"),"") | D14: =IFERROR(AVERAGEIFS(Videos!$AA$2:$AA$401,Videos!$D$2:$D$401,"Short"),"")
B15: Costo imputado total (USD) | C15: =SUMIFS(Videos!$Z$2:$Z$401,Videos!$D$2:$D$401,"Largo") -> 0 | D15: =SUMIFS(Videos!$Z$2:$Z$401,Videos!$D$2:$D$401,"Short") -> 0
B16: Ganadores (incluye provisionales) | C16: =COUNTIFS(Videos!$D$2:$D$401,"Largo",Videos!$AL$2:$AL$401,"Ganador*") -> 0 | D16: =COUNTIFS(Videos!$D$2:$D$401,"Short",Videos!$AL$2:$AL$401,"Ganador*") -> 0
B17: Perdedores (incluye provisionales) | C17: =COUNTIFS(Videos!$D$2:$D$401,"Largo",Videos!$AL$2:$AL$401,"Perdedor*") -> 0 | D17: =COUNTIFS(Videos!$D$2:$D$401,"Short",Videos!$AL$2:$AL$401,"Perdedor*") -> 0
B19: Medianas por formato (videos con dato)
C20: Largos | D20: Shorts
B21: CTR a 28 días | C21: {=IFERROR(MEDIAN(IF((Videos!$D$2:$D$401="Largo")*ISNUMBER(Videos!$P$2:$P$401),Videos!$P$2:$P$401)),"")} | D21: {=IFERROR(MEDIAN(IF((Videos!$D$2:$D$401="Short")*ISNUMBER(Videos!$P$2:$P$401),Videos!$P$2:$P$401)),"")}
B22: Duración media vista (min) | C22: {=IFERROR(MEDIAN(IF((Videos!$D$2:$D$401="Largo")*ISNUMBER(Videos!$Q$2:$Q$401),Videos!$Q$2:$Q$401)),"")} | D22: {=IFERROR(MEDIAN(IF((Videos!$D$2:$D$401="Short")*ISNUMBER(Videos!$Q$2:$Q$401),Videos!$Q$2:$Q$401)),"")}
B23: % visto | C23: {=IFERROR(MEDIAN(IF((Videos!$D$2:$D$401="Largo")*ISNUMBER(Videos!$R$2:$R$401),Videos!$R$2:$R$401)),"")} | D23: {=IFERROR(MEDIAN(IF((Videos!$D$2:$D$401="Short")*ISNUMBER(Videos!$R$2:$R$401),Videos!$R$2:$R$401)),"")}
B24: Retención a 30 s | C24: {=IFERROR(MEDIAN(IF((Videos!$D$2:$D$401="Largo")*ISNUMBER(Videos!$S$2:$S$401),Videos!$S$2:$S$401)),"")} | D24: {=IFERROR(MEDIAN(IF((Videos!$D$2:$D$401="Short")*ISNUMBER(Videos!$S$2:$S$401),Videos!$S$2:$S$401)),"")}
B25: Vistas a 28 días | C25: {=IFERROR(MEDIAN(IF((Videos!$D$2:$D$401="Largo")*ISNUMBER(Videos!$N$2:$N$401),Videos!$N$2:$N$401)),"")} | D25: {=IFERROR(MEDIAN(IF((Videos!$D$2:$D$401="Short")*ISNUMBER(Videos!$N$2:$N$401),Videos!$N$2:$N$401)),"")}
B26: Múltiplo a 28 días | C26: {=IFERROR(MEDIAN(IF((Videos!$D$2:$D$401="Largo")*ISNUMBER(Videos!$AJ$2:$AJ$401),Videos!$AJ$2:$AJ$401)),"")} | D26: {=IFERROR(MEDIAN(IF((Videos!$D$2:$D$401="Short")*ISNUMBER(Videos!$AJ$2:$AJ$401),Videos!$AJ$2:$AJ$401)),"")}
B28: Por pilar (solo largos)
C29: Largos con vistas a 28 d | D29: Mediana del múltiplo a 28 d | E29: Mediana de vistas a 28 d | F29: Mediana de % visto
